Traceback (most recent call last):
  File "/home/runner/.cache/pypoetry/virtualenvs/codino-TDIfPOj3-py3.9/lib/python3.9/site-packages/jupyter_cache/executors/utils.py", line 51, in single_nb_execution
    executenb(
  File "/home/runner/.cache/pypoetry/virtualenvs/codino-TDIfPOj3-py3.9/lib/python3.9/site-packages/nbclient/client.py", line 1117, in execute
    return NotebookClient(nb=nb, resources=resources, km=km, **kwargs).execute()
  File "/home/runner/.cache/pypoetry/virtualenvs/codino-TDIfPOj3-py3.9/lib/python3.9/site-packages/nbclient/util.py", line 78, in wrapped
    return just_run(coro(*args, **kwargs))
  File "/home/runner/.cache/pypoetry/virtualenvs/codino-TDIfPOj3-py3.9/lib/python3.9/site-packages/nbclient/util.py", line 57, in just_run
    return loop.run_until_complete(coro)
  File "/opt/hostedtoolcache/Python/3.9.7/x64/lib/python3.9/asyncio/base_events.py", line 642, in run_until_complete
    return future.result()
  File "/home/runner/.cache/pypoetry/virtualenvs/codino-TDIfPOj3-py3.9/lib/python3.9/site-packages/nbclient/client.py", line 558, in async_execute
    await self.async_execute_cell(
  File "/home/runner/.cache/pypoetry/virtualenvs/codino-TDIfPOj3-py3.9/lib/python3.9/site-packages/nbclient/client.py", line 862, in async_execute_cell
    self._check_raise_for_error(cell, exec_reply)
  File "/home/runner/.cache/pypoetry/virtualenvs/codino-TDIfPOj3-py3.9/lib/python3.9/site-packages/nbclient/client.py", line 765, in _check_raise_for_error
    raise CellExecutionError.from_cell_and_msg(cell, exec_reply_content)
nbclient.exceptions.CellExecutionError: An error occurred while executing the following cell:
------------------
c = codino.process.Converter()
------------------

[0;31m---------------------------------------------------------------------------[0m
[0;31mAttributeError[0m                            Traceback (most recent call last)
[0;32m/tmp/ipykernel_3511/2011635181.py[0m in [0;36m<module>[0;34m[0m
[0;32m----> 1[0;31m [0mc[0m [0;34m=[0m [0mcodino[0m[0;34m.[0m[0mprocess[0m[0;34m.[0m[0mConverter[0m[0;34m([0m[0;34m)[0m[0;34m[0m[0;34m[0m[0m
[0m
[0;31mAttributeError[0m: module 'codino' has no attribute 'process'
AttributeError: module 'codino' has no attribute 'process'

